Workbook

Sheet Sheet1
A1: Division - Subdivision | B1: Communities
A2: Fako - Buea | B2: Likoko Membea
A3: Fako - Buea | B3: Lysoka
A4: Fako - Buea | B4: Bitingui
A5: Fako - Buea | B5: Bokoko
A6: Fako - Buea | B6: Bokova
A7: Fako - Buea | B7: Sandpit
A8: Fako - Buea | B8: Bonduma
A9: Fako - Buea | B9: Bokwai
A10: Fako - Buea | B10: Bokwango
A11: Fako - Buea | B11: Bolifamba (Mile 16)
A12: Fako - Buea | B12: Bonakanda
... A104: BAMENDA IV | B104: Bambili

Sheet Data_Entry
I1: Sex workers | K1: Gender Minorities | M1: IDP | O1: Persons with disabilities | Q1: AGY-W | R1: ABY-M | U1: TOTAL
A2: Date | B2: Week | C2: Month | D2: Division - Subdivision | E2: Communities | F2: Thematic Area | G2: Age Group | H2: Project | I2: MALE | J2: FEMALE | K2: MALE: | L2: FEMALE: | M2: MALE. | N2: FEMALE. | O2: MALE- | P2: FEMALE- | Q2: FEMALE_ | R2: MALE_ | S2: WOMEN | T2: MEN | U2: Participants
B3: =WEEKNUM(A3) -> 0 | C3: =TEXT(A3,"mmm-yyyy") -> Jan-1900 | D3: =IFERROR(INDEX(Sheet1!$A$2:$A$104,MATCH(SessionData[[#This Row],[Communities]],Sheet1!$B$2:$B$104,0)),"") | U3: =SUM(SessionData[[#This Row],[MALE]:[MEN]]) -> 0
B4: =WEEKNUM(A4) -> 0 | C4: =TEXT(A4,"mmm-yyyy") -> Jan-1900 | D4: =IFERROR(INDEX(Sheet1!$A$2:$A$104,MATCH(SessionData[[#This Row],[Communities]],Sheet1!$B$2:$B$104,0)),"") | U4: =SUM(SessionData[[#This Row],[MALE]:[MEN]]) -> 0
B5: =WEEKNUM(A5) -> 0 | C5: =TEXT(A5,"mmm-yyyy") -> Jan-1900 | D5: =IFERROR(INDEX(Sheet1!$A$2:$A$104,MATCH(SessionData[[#This Row],[Communities]],Sheet1!$B$2:$B$104,0)),"") | U5: =SUM(SessionData[[#This Row],[MALE]:[MEN]]) -> 0
B6: =WEEKNUM(A6) -> 0 | C6: =TEXT(A6,"mmm-yyyy") -> Jan-1900 | D6: =IFERROR(INDEX(Sheet1!$A$2:$A$104,MATCH(SessionData[[#This Row],[Communities]],Sheet1!$B$2:$B$104,0)),"") | U6: =SUM(SessionData[[#This Row],[MALE]:[MEN]]) -> 0
B7: =WEEKNUM(A7) -> 0 | C7: =TEXT(A7,"mmm-yyyy") -> Jan-1900 | D7: =IFERROR(INDEX(Sheet1!$A$2:$A$104,MATCH(SessionData[[#This Row],[Communities]],Sheet1!$B$2:$B$104,0)),"") | U7: =SUM(SessionData[[#This Row],[MALE]:[MEN]]) -> 0
B8: =WEEKNUM(A8) -> 0 | C8: =TEXT(A8,"mmm-yyyy") -> Jan-1900 | D8: =IFERROR(INDEX(Sheet1!$A$2:$A$104,MATCH(SessionData[[#This Row],[Communities]],Sheet1!$B$2:$B$104,0)),"") | U8: =SUM(SessionData[[#This Row],[MALE]:[MEN]]) -> 0
B9: =WEEKNUM(A9) -> 0 | C9: =TEXT(A9,"mmm-yyyy") -> Jan-1900 | D9: =IFERROR(INDEX(Sheet1!$A$2:$A$104,MATCH(SessionData[[#This Row],[Communities]],Sheet1!$B$2:$B$104,0)),"") | U9: =SUM(SessionData[[#This Row],[MALE]:[MEN]]) -> 0
B10: =WEEKNUM(A10) -> 0 | C10: =TEXT(A10,"mmm-yyyy") -> Jan-1900 | D10: =IFERROR(INDEX(Sheet1!$A$2:$A$104,MATCH(SessionData[[#This Row],[Communities]],Sheet1!$B$2:$B$104,0)),"") | U10: =SUM(SessionData[[#This Row],[MALE]:[MEN]]) -> 0
B11: =WEEKNUM(A11) -> 0 | C11: =TEXT(A11,"mmm-yyyy") -> Jan-1900 | D11: =IFERROR(INDEX(Sheet1!$A$2:$A$104,MATCH(SessionData[[#This Row],[Communities]],Sheet1!$B$2:$B$104,0)),"") | U11: =SUM(SessionData[[#This Row],[MALE]:[MEN]]) -> 0
B12: =WEEKNUM(A12) -> 0 | C12: =TEXT(A12,"mmm-yyyy") -> Jan-1900 | D12: =IFERROR(INDEX(Sheet1!$A$2:$A$104,MATCH(SessionData[[#This Row],[Communities]],Sheet1!$B$2:$B$104,0)),"") | U12: =SUM(SessionData[[#This Row],[MALE]:[MEN]]) -> 0
B13: =WEEKNUM(A13) -> 0 | C13: =TEXT(A13,"mmm-yyyy") -> Jan-1900 | D13: =IFERROR(INDEX(Sheet1!$A$2:$A$104,MATCH(SessionData[[#This Row],[Communities]],Sheet1!$B$2:$B$104,0)),"") | U13: =SUM(SessionData[[#This Row],[MALE]:[MEN]]) -> 0
B14: =WEEKNUM(A14) -> 0 | C14: =TEXT(A14,"mmm-yyyy") -> Jan-1900 | D14: =IFERROR(INDEX(Sheet1!$A$2:$A$104,MATCH(SessionData[[#This Row],[Communities]],Sheet1!$B$2:$B$104,0)),"") | U14: =SUM(SessionData[[#This Row],[MALE]:[MEN]]) -> 0
... B201: =WEEKNUM(A201) -> 0 | C201: =TEXT(A201,"mmm-yyyy") -> Jan-1900 | D201: =IFERROR(INDEX(Sheet1!$A$2:$A$104,MATCH(SessionData[[#This Row],[Communities]],Sheet1!$B$2:$B$104,0)),"") | U201: =SUM(SessionData[[#This Row],[MALE]:[MEN]]) -> 0
B202: =WEEKNUM(A202) -> 0 | C202: =TEXT(A202,"mmm-yyyy") -> Jan-1900

Sheet Weekly_Monthly_Summary
A2: Month | B2: Participants | D2: Gender | E2: Participants
A3: Jan-2026 | B3: =SUMIF(Data_Entry!C:C,TEXT(A3,"mmm-yyyy"),Data_Entry!U:U) -> 0 | D3: Male | E3: =SUM(SessionData[MALE])+SUM(SessionData[MALE:])+SUM(SessionData[MALE.])+SUM(SessionData[MALE-])+SUM(SessionData[MALE_])+SessionData[[#This Row],[MEN]] -> 0
A4: Feb-2026 | B4: =SUMIF(Data_Entry!C:C,TEXT(A4,"mmm-yyyy"),Data_Entry!U:U) -> 0 | D4: Female | E4: =SUM(SessionData[FEMALE])+SUM(SessionData[FEMALE:])+SUM(SessionData[FEMALE.])+SUM(SessionData[FEMALE-])+SUM(SessionData[FEMALE_])+Data_Entry!S3 -> 0
A5: Mar-2026 | B5: =SUMIF(Data_Entry!C:C,TEXT(A5,"mmm-yyyy"),Data_Entry!U:U) -> 0 | D5: Other | E5: =0 -> 0
A6: Apr-2026 | B6: =SUMIF(Data_Entry!C:C,TEXT(A6,"mmm-yyyy"),Data_Entry!U:U) -> 0
A7: May-2026 | B7: =SUMIF(Data_Entry!C:C,TEXT(A7,"mmm-yyyy"),Data_Entry!U:U) -> 0 | D7: Target | E7: Participants
A8: Jun-2026 | B8: =SUMIF(Data_Entry!C:C,TEXT(A8,"mmm-yyyy"),Data_Entry!U:U) -> 0 | D8: =Data_Entry!I1 -> Sex workers | E8: =SUM(Data_Entry!I:J) -> 0
A9: Jul-2026 | B9: =SUMIF(Data_Entry!C:C,TEXT(A9,"mmm-yyyy"),Data_Entry!U:U) -> 0 | D9: =Data_Entry!K1 -> Gender Minorities | E9: =SUM(Data_Entry!K:L) -> 0
A10: Aug-2026 | B10: =SUMIF(Data_Entry!C:C,TEXT(A10,"mmm-yyyy"),Data_Entry!U:U) -> 0 | D10: =Data_Entry!M1 -> IDP | E10: =SUM(Data_Entry!M:N) -> 0
A11: Sep-2026 | B11: =SUMIF(Data_Entry!C:C,TEXT(A11,"mmm-yyyy"),Data_Entry!U:U) -> 0 | D11: =Data_Entry!O1 -> Persons with disabilities | E11: =SUM(Data_Entry!O:P) -> 0
A12: Oct-2026 | B12: =SUMIF(Data_Entry!C:C,TEXT(A12,"mmm-yyyy"),Data_Entry!U:U) -> 0 | D12: =Data_Entry!Q1 -> AGY-W | E12: =SUM(Data_Entry!Q:Q) -> 0
A13: Nov-2026 | B13: =SUMIF(Data_Entry!C:C,TEXT(A13,"mmm-yyyy"),Data_Entry!U:U) -> 0 | D13: =Data_Entry!R1 -> ABY-M | E13: =SUM(Data_Entry!R:R) -> 0
A14: Dec-2026 | B14: =SUMIF(Data_Entry!C:C,TEXT(A14,"mmm-yyyy"),Data_Entry!U:U) -> 0 | D14: =SessionData[[#Headers],[WOMEN]] -> WOMEN | E14: =SUM(Data_Entry!S:S) -> 0
D15: =SessionData[[#Headers],[MEN]] -> MEN | E15: =SUM(Data_Entry!T:T) -> 0

Sheet Dashboard
A1: VISION IN ACTION CAMEROON COMMUNITY SESSIONS DASHBOARD
B2: Total Participants | C2: =SUM(Data_Entry!U:U) -> 0
B3: Total Sessions | C3: =COUNTA(Data_Entry!A:A)-1 -> 0

Sheet Pivot_Community
A2: =SessionData[[#Headers],[Communities]] -> Communities | B2: Participants | D2: =SessionData[[#Headers],[Division - Subdivision]] -> Division - Subdivision | E2: Participants
A3: {=_xlfn._xlws.SORT(_xlfn.UNIQUE(_xlfn._xlws.FILTER(TRIM(SessionData[Communities]), (TRIM(SessionData[Communities])<>"")*(TRIM(SessionData[Communities])<>"0"))))} -> #VALUE! | B3: {=IF(A3="","",SUMPRODUCT((TRIM(SessionData[Communities])=A3)*(SessionData[Participants])))} -> #VALUE! | D3: {=_xlfn._xlws.SORT(_xlfn.UNIQUE(_xlfn._xlws.FILTER(TRIM(SessionData[Division - Subdivision]), (TRIM(SessionData[Division - Subdivision])<>"")*(TRIM(SessionData[Division - Subdivision])<>"0"))))} -> #VALUE! | E3: {=IF(D3="","",SUMPRODUCT((TRIM(SessionData[Division - Subdivision])=D3)*(SessionData[Participants])))} -> #VALUE!
B4: {=IF(A4="","",SUMPRODUCT((TRIM(SessionData[Communities])=A4)*(SessionData[Participants])))} | E4: {=IF(D4="","",SUMPRODUCT((TRIM(SessionData[Division - Subdivision])=D4)*(SessionData[Participants])))}
B5: {=IF(A5="","",SUMPRODUCT((TRIM(SessionData[Communities])=A5)*(SessionData[Participants])))} | E5: {=IF(D5="","",SUMPRODUCT((TRIM(SessionData[Division - Subdivision])=D5)*(SessionData[Participants])))}
B6: {=IF(A6="","",SUMPRODUCT((TRIM(SessionData[Communities])=A6)*(SessionData[Participants])))} | E6: {=IF(D6="","",SUMPRODUCT((TRIM(SessionData[Division - Subdivision])=D6)*(SessionData[Participants])))}
B7: {=IF(A7="","",SUMPRODUCT((TRIM(SessionData[Communities])=A7)*(SessionData[Participants])))} | E7: {=IF(D7="","",SUMPRODUCT((TRIM(SessionData[Division - Subdivision])=D7)*(SessionData[Participants])))}
B8: {=IF(A8="","",SUMPRODUCT((TRIM(SessionData[Communities])=A8)*(SessionData[Participants])))} | E8: {=IF(D8="","",SUMPRODUCT((TRIM(SessionData[Division - Subdivision])=D8)*(SessionData[Participants])))}
B9: {=IF(A9="","",SUMPRODUCT((TRIM(SessionData[Communities])=A9)*(SessionData[Participants])))} | E9: {=IF(D9="","",SUMPRODUCT((TRIM(SessionData[Division - Subdivision])=D9)*(SessionData[Participants])))}
B10: {=IF(A10="","",SUMPRODUCT((TRIM(SessionData[Communities])=A10)*(SessionData[Participants])))}
B11: {=IF(A11="","",SUMPRODUCT((TRIM(SessionData[Communities])=A11)*(SessionData[Participants])))}
B12: {=IF(A12="","",SUMPRODUCT((TRIM(SessionData[Communities])=A12)*(SessionData[Participants])))}
B13: {=IF(A13="","",SUMPRODUCT((TRIM(SessionData[Communities])=A13)*(SessionData[Participants])))}
B14: {=IF(A14="","",SUMPRODUCT((TRIM(SessionData[Communities])=A14)*(SessionData[Participants])))}
B15: {=IF(A15="","",SUMPRODUCT((TRIM(SessionData[Communities])=A15)*(SessionData[Participants])))}
B16: {=IF(A16="","",SUMPRODUCT((TRIM(SessionData[Communities])=A16)*(SessionData[Participants])))}
B17: {=IF(A17="","",SUMPRODUCT((TRIM(SessionData[Communities])=A17)*(SessionData[Participants])))}
B18: {=IF(A18="","",SUMPRODUCT((TRIM(SessionData[Communities])=A18)*(SessionData[Participants])))}
B19: {=IF(A19="","",SUMPRODUCT((TRIM(SessionData[Communities])=A19)*(SessionData[Participants])))}
B20: {=IF(A20="","",SUMPRODUCT((TRIM(SessionData[Communities])=A20)*(SessionData[Participants])))}
B21: {=IF(A21="","",SUMPRODUCT((TRIM(SessionData[Communities])=A21)*(SessionData[Participants])))}

Sheet Pivot_Thematic
A2: Thematic Area | B2: Participants
A3: {=_xlfn._xlws.SORT(_xlfn.UNIQUE(_xlfn._xlws.FILTER(TRIM(SessionData[Thematic Area]), (TRIM(SessionData[Thematic Area])<>"")*(TRIM(SessionData[Thematic Area])<>"0"))))} -> #VALUE! | B3: {=IF(A3="","",SUMPRODUCT((TRIM(SessionData[Thematic Area])=A3)*(SessionData[Participants])))} -> #VALUE!
B4: {=IF(A4="","",SUMPRODUCT((TRIM(SessionData[Thematic Area])=A4)*(SessionData[Participants])))}
B5: {=IF(A5="","",SUMPRODUCT((TRIM(SessionData[Thematic Area])=A5)*(SessionData[Participants])))}
B6: {=IF(A6="","",SUMPRODUCT((TRIM(SessionData[Thematic Area])=A6)*(SessionData[Participants])))}
B7: {=IF(A7="","",SUMPRODUCT((TRIM(SessionData[Thematic Area])=A7)*(SessionData[Participants])))}
B8: {=IF(A8="","",SUMPRODUCT((TRIM(SessionData[Thematic Area])=A8)*(SessionData[Participants])))}
B9: {=IF(A9="","",SUMPRODUCT((TRIM(SessionData[Thematic Area])=A9)*(SessionData[Participants])))}
B10: {=IF(A10="","",SUMPRODUCT((TRIM(SessionData[Thematic Area])=A10)*(SessionData[Participants])))}
B11: {=IF(A11="","",SUMPRODUCT((TRIM(SessionData[Thematic Area])=A11)*(SessionData[Participants])))}
B12: {=IF(A12="","",SUMPRODUCT((TRIM(SessionData[Thematic Area])=A12)*(SessionData[Participants])))}
B13: {=IF(A13="","",SUMPRODUCT((TRIM(SessionData[Thematic Area])=A13)*(SessionData[Participants])))}
B14: {=IF(A14="","",SUMPRODUCT((TRIM(SessionData[Thematic Area])=A14)*(SessionData[Participants])))}
B15: {=IF(A15="","",SUMPRODUCT((TRIM(SessionData[Thematic Area])=A15)*(SessionData[Participants])))}
... B21: {=IF(A21="","",SUMPRODUCT((TRIM(SessionData[Thematic Area])=A21)*(SessionData[Participants])))}

Sheet Pivot_Project
A2: Project | B2: Participants
A3: {=_xlfn._xlws.SORT(_xlfn.UNIQUE(_xlfn._xlws.FILTER(TRIM(SessionData[Project]), (TRIM(SessionData[Project])<>"")*(TRIM(SessionData[Project])<>"0"))))} -> #VALUE! | B3: {=IF(A3="","",SUMPRODUCT((TRIM(SessionData[Project])=A3)*(SessionData[Participants])))} -> #VALUE!
B4: {=IF(A4="","",SUMPRODUCT((TRIM(SessionData[Project])=A4)*(SessionData[Participants])))}
B5: {=IF(A5="","",SUMPRODUCT((TRIM(SessionData[Project])=A5)*(SessionData[Participants])))}
B6: {=IF(A6="","",SUMPRODUCT((TRIM(SessionData[Project])=A6)*(SessionData[Participants])))}
B7: {=IF(A7="","",SUMPRODUCT((TRIM(SessionData[Project])=A7)*(SessionData[Participants])))}
B8: {=IF(A8="","",SUMPRODUCT((TRIM(SessionData[Project])=A8)*(SessionData[Participants])))}
B9: {=IF(A9="","",SUMPRODUCT((TRIM(SessionData[Project])=A9)*(SessionData[Participants])))}
B10: {=IF(A10="","",SUMPRODUCT((TRIM(SessionData[Project])=A10)*(SessionData[Participants])))}
B11: {=IF(A11="","",SUMPRODUCT((TRIM(SessionData[Project])=A11)*(SessionData[Participants])))}
B12: {=IF(A12="","",SUMPRODUCT((TRIM(SessionData[Project])=A12)*(SessionData[Participants])))}
B13: {=IF(A13="","",SUMPRODUCT((TRIM(SessionData[Project])=A13)*(SessionData[Participants])))}
B14: {=IF(A14="","",SUMPRODUCT((TRIM(SessionData[Project])=A14)*(SessionData[Participants])))}
B15: {=IF(A15="","",SUMPRODUCT((TRIM(SessionData[Project])=A15)*(SessionData[Participants])))}
... B21: {=IF(A21="","",SUMPRODUCT((TRIM(SessionData[Project])=A21)*(SessionData[Participants])))}

Sheet Pivot_Age_Group
A2: Age Group | B2: Participants
A3: {=_xlfn._xlws.SORT(_xlfn.UNIQUE(_xlfn._xlws.FILTER(TRIM(SessionData[Age Group]), (TRIM(SessionData[Age Group])<>"")*(TRIM(SessionData[Age Group])<>"0"))))} -> #VALUE! | B3: {=IF(A3="","",SUMPRODUCT((TRIM(SessionData[Age Group])=A3)*(SessionData[Participants])))} -> #VALUE!
B4: {=IF(A4="","",SUMPRODUCT((TRIM(SessionData[Age Group])=A4)*(SessionData[Participants])))}
B5: {=IF(A5="","",SUMPRODUCT((TRIM(SessionData[Age Group])=A5)*(SessionData[Participants])))}
B6: {=IF(A6="","",SUMPRODUCT((TRIM(SessionData[Age Group])=A6)*(SessionData[Participants])))}
B7: {=IF(A7="","",SUMPRODUCT((TRIM(SessionData[Age Group])=A7)*(SessionData[Participants])))}
B8: {=IF(A8="","",SUMPRODUCT((TRIM(SessionData[Age Group])=A8)*(SessionData[Participants])))}
B9: {=IF(A9="","",SUMPRODUCT((TRIM(SessionData[Age Group])=A9)*(SessionData[Participants])))}
B10: {=IF(A10="","",SUMPRODUCT((TRIM(SessionData[Age Group])=A10)*(SessionData[Participants])))}
B11: {=IF(A11="","",SUMPRODUCT((TRIM(SessionData[Age Group])=A11)*(SessionData[Participants])))}
B12: {=IF(A12="","",SUMPRODUCT((TRIM(SessionData[Age Group])=A12)*(SessionData[Participants])))}
B13: {=IF(A13="","",SUMPRODUCT((TRIM(SessionData[Age Group])=A13)*(SessionData[Participants])))}
B14: {=IF(A14="","",SUMPRODUCT((TRIM(SessionData[Age Group])=A14)*(SessionData[Participants])))}
B15: {=IF(A15="","",SUMPRODUCT((TRIM(SessionData[Age Group])=A15)*(SessionData[Participants])))}
... B21: {=IF(A21="","",SUMPRODUCT((TRIM(SessionData[Age Group])=A21)*(SessionData[Participants])))}

Sheet Narrative_Report
A1: VISION IN ACTION CAMEROON COMMUNITY OUTREACH SESSIONS
A2: MONTHLY NARRATIVE REPORT
A5: REPORTING PERIOD
A6: =TEXT(TODAY(),"MMMM YYYY") -> August 2026
A8: 1. EXECUTIVE SUMMARY
A9: ="During the reporting period, community outreach sessions were conducted across Fako Division targeting Internally Displaced Persons (IDPs), host communities, women, men, girls and boys. A total of "&Dashboard!C3&" sessions reached "&Dashboard!C2&" participants across multiple communities and thematic areas." -> During the reporting period, community outreach sessions were conducted across Fako Division targeting Internally Displaced Persons (IDPs), host communities, women, men, girls and boys. A total of 0 sessions reached 0 participants across multiple communities and thematic areas.
A11: 2. KEY STATISTICS
A12: ="• Total Sessions Conducted: "&Dashboard!C3 -> • Total Sessions Conducted: 0
A13: ="• Total Participants Reached: "&Dashboard!C2 -> • Total Participants Reached: 0
A14: ="• Male Participants: "&Weekly_Monthly_Summary!E3&" ("&TEXT(Weekly_Monthly_Summary!E3/Dashboard!C2,"0%")&")" -> #DIV/0!
A15: ="• Female Participants: "&Weekly_Monthly_Summary!E4&" ("&TEXT(Weekly_Monthly_Summary!E4/Dashboard!C2,"0%")&")" -> #DIV/0!
A17: 3. COMMUNITY BREAKDOWN
A18: ="Sessions were conducted in the following communities:" -> Sessions were conducted in the following communities:
A19: =" • "&Pivot_Community!A3&": "&Pivot_Community!B3&" participants" -> #VALUE!
A20: =" • "&Pivot_Community!A4&": "&Pivot_Community!B4&" participants" -> • : participants
A21: =" • "&Pivot_Community!A5&": "&Pivot_Community!B5&" participants" -> • : participants
A22: =" • "&Pivot_Community!A6&": "&Pivot_Community!B6&" participants" -> • : participants
A23: =" • "&Pivot_Community!A7&": "&Pivot_Community!B7&" participants" -> • : participants
A24: =" • "&Pivot_Community!A8&": "&Pivot_Community!B8&" participants" -> • : participants
A25: =" • "&Pivot_Community!A9&": "&Pivot_Community!B9&" participants" -> • : participants
A26: =" • "&Pivot_Community!A10&": "&Pivot_Community!B10&" participants" -> • : participants
A27: =" • "&Pivot_Community!A11&": "&Pivot_Community!B11&" participants" -> • : participants
A28: =" • "&Pivot_Community!A12&": "&Pivot_Community!B12&" participants" -> • : participants
A29: =" • "&Pivot_Community!A13&": "&Pivot_Community!B13&" participants" -> • : participants
A30: =" • "&Pivot_Community!A14&": "&Pivot_Community!B14&" participants" -> • : participants
... A40: =" • "&Pivot_Community!A24&": "&Pivot_Community!B24&" participants" -> • : participants
A42: 4. THEMATIC AREAS COVERED
A43: ="Sessions addressed the following thematic areas:" -> Sessions addressed the following thematic areas:
A44: =" • "&Pivot_Thematic!A3&": "&Pivot_Thematic!B3&" participants" -> #VALUE!
A45: =" • "&Pivot_Thematic!A4&": "&Pivot_Thematic!B4&" participants" -> • : participants
A46: =" • "&Pivot_Thematic!A5&": "&Pivot_Thematic!B5&" participants" -> • : participants
A48: 5. AGE GROUP DISTRIBUTION
A49: ="Participants were distributed across the following age groups:" -> Participants were distributed across the following age groups:
A50: =" • "&Pivot_Age_Group!A3&": "&Pivot_Age_Group!B3&" participants ("&TEXT(Pivot_Age_Group!B3/Dashboard!C2,"0%")&")" -> #VALUE!
A51: =" • "&Pivot_Age_Group!A4&": "&Pivot_Age_Group!B4&" participants ("&TEXT(Pivot_Age_Group!B4/Dashboard!C2,"0%")&")" -> #VALUE!
A52: =" • "&Pivot_Age_Group!A5&": "&Pivot_Age_Group!B5&" participants ("&TEXT(Pivot_Age_Group!B5/Dashboard!C2,"0%")&")" -> #VALUE!
A54: 6. TARGET POPULATIONS REACHED
A55: ="The following vulnerable and key populations were reached:" -> The following vulnerable and key populations were reached:
A56: =" • Sex Workers: "&Weekly_Monthly_Summary!E8&" participants" -> • Sex Workers: 0 participants
A57: =" • Gender Minorities: "&Weekly_Monthly_Summary!E9&" participants" -> • Gender Minorities: 0 participants
...
